exception TestException;


void function main() {
    handle (TestException) {
        println("Done");
    } try {
        raise TestException("true");
    }
}
